{"uuid": "359a3962-b93d-4be5-b25f-75006345095e", "children": ["8847fa42-9741-4289-86ec-fc2edf6648c0"], "befores": [{"name": "_Class__pytest_setup_class", "status": "broken", "statusDetails": {"message": "urllib3.exceptions.MaxRetryError: HTTPConnectionPool(host='127.0.0.1', port=4723): Max retries exceeded with url: /wd/hub/session (Caused by NewConnectionError('<urllib3.connection.HTTPConnection object at 0x000001895FB43EB0>: Failed to establish a new connection: [WinError 10061] 由于目标计算机积极拒绝，无法连接。'))\n", "trace": "  File \"e:\\python3.8\\lib\\site-packages\\pluggy\\callers.py\", line 187, in _multicall\n    res = hook_impl.function(*args)\n  File \"e:\\python3.8\\lib\\site-packages\\_pytest\\fixtures.py\", line 958, in pytest_fixture_setup\n    result = call_fixture_func(fixturefunc, request, kwargs)\n  File \"e:\\python3.8\\lib\\site-packages\\_pytest\\fixtures.py\", line 784, in call_fixture_func\n    res = next(it)\n  File \"e:\\python3.8\\lib\\site-packages\\_pytest\\python.py\", line 722, in xunit_setup_class_fixture\n    _call_with_optional_argument(func, self.obj)\n  File \"e:\\python3.8\\lib\\site-packages\\_pytest\\python.py\", line 660, in _call_with_optional_argument\n    func(arg)\n  File \"E:\\数据分析\\scripts\\test_wechat_mini.py\", line 13, in setup_class\n    self.driver = set_tear().setup('com.tencent.mm', '.ui.LauncherUI')\n  File \"E:\\数据分析\\base\\set_tear.py\", line 13, in setup\n    self.driver = webdriver.Remote('http://127.0.0.1:4723/wd/hub', desire_caps)\n  File \"e:\\python3.8\\lib\\site-packages\\appium\\webdriver\\webdriver.py\", line 147, in __init__\n    super(WebDriver, self).__init__(\n  File \"e:\\python3.8\\lib\\site-packages\\selenium\\webdriver\\remote\\webdriver.py\", line 157, in __init__\n    self.start_session(capabilities, browser_profile)\n  File \"e:\\python3.8\\lib\\site-packages\\appium\\webdriver\\webdriver.py\", line 227, in start_session\n    response = self.execute(RemoteCommand.NEW_SESSION, parameters)\n  File \"e:\\python3.8\\lib\\site-packages\\selenium\\webdriver\\remote\\webdriver.py\", line 319, in execute\n    response = self.command_executor.execute(driver_command, params)\n  File \"e:\\python3.8\\lib\\site-packages\\selenium\\webdriver\\remote\\remote_connection.py\", line 374, in execute\n    return self._request(command_info[0], url, body=data)\n  File \"e:\\python3.8\\lib\\site-packages\\selenium\\webdriver\\remote\\remote_connection.py\", line 397, in _request\n    resp = self._conn.request(method, url, body=body, headers=headers)\n  File \"e:\\python3.8\\lib\\site-packages\\urllib3\\request.py\", line 79, in request\n    return self.request_encode_body(\n  File \"e:\\python3.8\\lib\\site-packages\\urllib3\\request.py\", line 171, in request_encode_body\n    return self.urlopen(method, url, **extra_kw)\n  File \"e:\\python3.8\\lib\\site-packages\\urllib3\\poolmanager.py\", line 330, in urlopen\n    response = conn.urlopen(method, u.request_uri, **kw)\n  File \"e:\\python3.8\\lib\\site-packages\\urllib3\\connectionpool.py\", line 747, in urlopen\n    return self.urlopen(\n  File \"e:\\python3.8\\lib\\site-packages\\urllib3\\connectionpool.py\", line 747, in urlopen\n    return self.urlopen(\n  File \"e:\\python3.8\\lib\\site-packages\\urllib3\\connectionpool.py\", line 747, in urlopen\n    return self.urlopen(\n  File \"e:\\python3.8\\lib\\site-packages\\urllib3\\connectionpool.py\", line 719, in urlopen\n    retries = retries.increment(\n  File \"e:\\python3.8\\lib\\site-packages\\urllib3\\util\\retry.py\", line 436, in increment\n    raise MaxRetryError(_pool, url, error or ResponseError(cause))\n"}, "start": 1595226445947, "stop": 1595226455107}], "start": 1595226445947, "stop": 1595226456203}